2024-08-04 04:10:10,332:INFO:discord.gateway: Shard ID None has connected to Gateway (Session ID: 167de5470acca7b53a6cee6438f2c077).
2024-08-04 04:10:31,051:ERROR:discord.app_commands.tree: Ignoring exception in command 'summarize'
Traceback (most recent call last):
  File "/home/runner/stellar/.pythonlibs/lib/python3.12/site-packages/aiohttp/connector.py", line 1203, in _create_direct_connection
    hosts = await self._resolve_host(host, port, traces=traces)
            ^^^^^^^^^^^^^^^^^^^^^^^^^^^^^^^^^^^^^^^^^^^^^^^^^^^
  File "/home/runner/stellar/.pythonlibs/lib/python3.12/site-packages/aiohttp/connector.py", line 880, in _resolve_host
    return await asyncio.shield(resolved_host_task)
           ^^^^^^^^^^^^^^^^^^^^^^^^^^^^^^^^^^^^^^^^
  File "/home/runner/stellar/.pythonlibs/lib/python3.12/site-packages/aiohttp/connector.py", line 917, in _resolve_host_with_throttle
    addrs = await self._resolver.resolve(host, port, family=self._family)
            ^^^^^^^^^^^^^^^^^^^^^^^^^^^^^^^^^^^^^^^^^^^^^^^^^^^^^^^^^^^^^
  File "/home/runner/stellar/.pythonlibs/lib/python3.12/site-packages/aiohttp/resolver.py", line 33, in resolve
    infos = await self._loop.getaddrinfo(
            ^^^^^^^^^^^^^^^^^^^^^^^^^^^^^
  File "/nix/store/lzvsvd9cgd3kgdndcbj1y3fjznz2a8g1-python3-3.12.3/lib/python3.12/asyncio/base_events.py", line 901, in getaddrinfo
    return await self.run_in_executor(
           ^^^^^^^^^^^^^^^^^^^^^^^^^^^
  File "/nix/store/lzvsvd9cgd3kgdndcbj1y3fjznz2a8g1-python3-3.12.3/lib/python3.12/concurrent/futures/thread.py", line 58, in run
    result = self.fn(*self.args, **self.kwargs)
             ^^^^^^^^^^^^^^^^^^^^^^^^^^^^^^^^^^
  File "/nix/store/lzvsvd9cgd3kgdndcbj1y3fjznz2a8g1-python3-3.12.3/lib/python3.12/socket.py", line 963, in getaddrinfo
    for res in _socket.getaddrinfo(host, port, family, type, proto, flags):
               ^^^^^^^^^^^^^^^^^^^^^^^^^^^^^^^^^^^^^^^^^^^^^^^^^^^^^^^^^^^
socket.gaierror: [Errno -2] Name or service not known

The above exception was the direct cause of the following exception:

Traceback (most recent call last):
  File "/home/runner/stellar/.pythonlibs/lib/python3.12/site-packages/discord/app_commands/commands.py", line 857, in _do_call
    return await self._callback(self.binding, interaction, **params)  # type: ignore
           ^^^^^^^^^^^^^^^^^^^^^^^^^^^^^^^^^^^^^^^^^^^^^^^^^^^^^^^^^
  File "/home/runner/stellar/cogs/summarize.py", line 25, in summarize
    summary, thumbnail_url = await get_summary(url, api_key)
                             ^^^^^^^^^^^^^^^^^^^^^^^^^^^^^^^
  File "/home/runner/stellar/summary.py", line 11, in get_summary
    return await summarize_website(url, api_key)
           ^^^^^^^^^^^^^^^^^^^^^^^^^^^^^^^^^^^^^
  File "/home/runner/stellar/summary.py", line 43, in summarize_website
    summary = await summarize_text(text, api_key)
              ^^^^^^^^^^^^^^^^^^^^^^^^^^^^^^^^^^^
  File "/home/runner/stellar/summary.py", line 60, in summarize_text
    async with session.post(url, headers=headers, json=data) as response:
  File "/home/runner/stellar/.pythonlibs/lib/python3.12/site-packages/aiohttp/client.py", line 1197, in __aenter__
    self._resp = await self._coro
                 ^^^^^^^^^^^^^^^^
  File "/home/runner/stellar/.pythonlibs/lib/python3.12/site-packages/aiohttp/client.py", line 581, in _request
    conn = await self._connector.connect(
           ^^^^^^^^^^^^^^^^^^^^^^^^^^^^^^
  File "/home/runner/stellar/.pythonlibs/lib/python3.12/site-packages/aiohttp/connector.py", line 544, in connect
    proto = await self._create_connection(req, traces, timeout)
            ^^^^^^^^^^^^^^^^^^^^^^^^^^^^^^^^^^^^^^^^^^^^^^^^^^^
  File "/home/runner/stellar/.pythonlibs/lib/python3.12/site-packages/aiohttp/connector.py", line 944, in _create_connection
    _, proto = await self._create_direct_connection(req, traces, timeout)
               ^^^^^^^^^^^^^^^^^^^^^^^^^^^^^^^^^^^^^^^^^^^^^^^^^^^^^^^^^^
  File "/home/runner/stellar/.pythonlibs/lib/python3.12/site-packages/aiohttp/connector.py", line 1209, in _create_direct_connection
    raise ClientConnectorError(req.connection_key, exc) from exc
aiohttp.client_exceptions.ClientConnectorError: Cannot connect to host api.genai.io:443 ssl:default [Name or service not known]

The above exception was the direct cause of the following exception:

Traceback (most recent call last):
  File "/home/runner/stellar/.pythonlibs/lib/python3.12/site-packages/discord/app_commands/tree.py", line 1310, in _call
    await command._invoke_with_namespace(interaction, namespace)
  File "/home/runner/stellar/.pythonlibs/lib/python3.12/site-packages/discord/app_commands/commands.py", line 883, in _invoke_with_namespace
    return await self._do_call(interaction, transformed_values)
           ^^^^^^^^^^^^^^^^^^^^^^^^^^^^^^^^^^^^^^^^^^^^^^^^^^^^
  File "/home/runner/stellar/.pythonlibs/lib/python3.12/site-packages/discord/app_commands/commands.py", line 876, in _do_call
    raise CommandInvokeError(self, e) from e
discord.app_commands.errors.CommandInvokeError: Command 'summarize' raised an exception: ClientConnectorError: Cannot connect to host api.genai.io:443 ssl:default [Name or service not known]
